<?xml version="1.0" encoding="utf-8"?>
<!-- This URDF was automatically created by SolidWorks to URDF Exporter! Originally created by Stephen Brawner (brawner@gmail.com) 
     Commit Version: 1.5.1-0-g916b5db  Build Version: 1.5.7152.31018
     For more information, please see http://wiki.ros.org/sw_urdf_exporter -->
<robot
  name="linkerhand_lhg20_left">
  <link
    name="wrist_base_link">
    <inertial>
      <origin
        xyz="-0.00155361355114024 -0.000106063589230238 0.0734079207843382"
        rpy="0 0 0" />
      <mass
        value="0.128209653942464" />
      <inertia
        ixx="0.000275064302939347"
        ixy="-3.19165289015563E-07"
        ixz="-4.59582398004926E-07"
        iyy="0.000171989789207224"
        iyz="5.01216411431013E-06"
        izz="0.000119247349135797" />
    </inertial>
    <visual>
      <origin
        xyz="0 0 0"
        rpy="0 0 0" />
      <geometry>
        <mesh
          filename="meshes/wrist_base_link.STL" />
      </geometry>
      <material
        name="">
        <color
          rgba="0.792156862745098 0.819607843137255 0.929411764705882 1" />
      </material>
    </visual>
    <collision>
      <origin
        xyz="0 0 0"
        rpy="0 0 0" />
      <geometry>
        <mesh
          filename="meshes/wrist_base_link.STL" />
      </geometry>
    </collision>
  </link>
  <link
    name="pinky_metacarpals">
    <inertial>
      <origin
        xyz="0.00922348527705086 2.30814137295587E-05 0.0496731670843109"
        rpy="0 0 0" />
      <mass
        value="0.0106056296377504" />
      <inertia
        ixx="1.23475262357064E-06"
        ixy="-4.66301113814371E-10"
        ixz="9.99490010734575E-08"
        iyy="1.22617089110441E-06"
        iyz="-9.43338934162942E-10"
        izz="4.36646097357804E-07" />
    </inertial>
    <visual>
      <origin
        xyz="0 0 0"
        rpy="0 0 0" />
      <geometry>
        <mesh
          filename="meshes/pinky_metacarpals.STL" />
      </geometry>
      <material
        name="">
        <color
          rgba="0.792156862745098 0.819607843137255 0.929411764705882 1" />
      </material>
    </visual>
    <collision>
      <origin
        xyz="0 0 0"
        rpy="0 0 0" />
      <geometry>
        <mesh
          filename="meshes/pinky_metacarpals.STL" />
      </geometry>
    </collision>
  </link>
  <joint
    name="pinky_mcp_roll"
    type="revolute">
    <origin
      xyz="-0.0098 0.03525 0.1436"
      rpy="0 0 0" />
    <parent
      link="wrist_base_link" />
    <child
      link="pinky_metacarpals" />
    <axis
      xyz="-1 0 0" />
    <limit
      lower="-0.26"
      upper="0.26"
      effort="1"
      velocity="1" />
  </joint>
  <link
    name="pinky_proximal">
    <inertial>
      <origin
        xyz="-0.0010976140677302 2.396378761646E-05 0.0515721107983493"
        rpy="0 0 0" />
      <mass
        value="0.01021511830474" />
      <inertia
        ixx="1.22426283256322E-06"
        ixy="-4.66301113814279E-10"
        ixz="9.99490010734579E-08"
        iyy="1.21857209153141E-06"
        iyz="-9.43338934162607E-10"
        izz="4.2111595421601E-07" />
    </inertial>
    <visual>
      <origin
        xyz="0 0 0"
        rpy="0 0 0" />
      <geometry>
        <mesh
          filename="meshes/pinky_proximal.STL" />
      </geometry>
      <material
        name="">
        <color
          rgba="0.792156862745098 0.819607843137255 0.929411764705882 1" />
      </material>
    </visual>
    <collision>
      <origin
        xyz="0 0 0"
        rpy="0 0 0" />
      <geometry>
        <mesh
          filename="meshes/pinky_proximal.STL" />
      </geometry>
    </collision>
  </link>
  <joint
    name="pinky_mcp_pitch"
    type="revolute">
    <origin
      xyz="0.0105 0 0"
      rpy="0 0 0" />
    <parent
      link="pinky_metacarpals" />
    <child
      link="pinky_proximal" />
    <axis
      xyz="0 1 0" />
    <limit
      lower="0"
      upper="1.3"
      effort="1"
      velocity="1" />
  </joint>
  <link
    name="pinky_middle">
    <inertial>
      <origin
        xyz="0.00153702581546594 1.43440286837493E-05 0.0294794846937131"
        rpy="0 0 0" />
      <mass
        value="0.00570037002681658" />
      <inertia
        ixx="4.91195532965659E-07"
        ixy="-4.85869568712967E-10"
        ixz="3.69080634056836E-08"
        iyy="4.46377269182336E-07"
        iyz="-1.11190314093907E-09"
        izz="2.67214139994489E-07" />
    </inertial>
    <visual>
      <origin
        xyz="0 0 0"
        rpy="0 0 0" />
      <geometry>
        <mesh
          filename="meshes/pinky_middle.STL" />
      </geometry>
      <material
        name="">
        <color
          rgba="0.792156862745098 0.819607843137255 0.929411764705882 1" />
      </material>
    </visual>
    <collision>
      <origin
        xyz="0 0 0"
        rpy="0 0 0" />
      <geometry>
        <mesh
          filename="meshes/pinky_middle.STL" />
      </geometry>
    </collision>
  </link>
  <joint
    name="pinky_pip"
    type="revolute">
    <origin
      xyz="-0.00349999999999933 0 0.0448999999999999"
      rpy="0 0 0" />
    <parent
      link="pinky_proximal" />
    <child
      link="pinky_middle" />
    <axis
      xyz="0 1 0" />
    <limit
      lower="0"
      upper="1.42"
      effort="1"
      velocity="1" />
  </joint>
  <link
    name="pinky_distal">
    <inertial>
      <origin
        xyz="-0.00654409960736848 -3.01856172779669E-07 0.00867928569364862"
        rpy="0 0 0" />
      <mass
        value="0.00313066685350453" />
      <inertia
        ixx="2.09660669757746E-07"
        ixy="1.40992256446428E-11"
        ixz="5.29697035540311E-08"
        iyy="2.07629430298593E-07"
        iyz="4.76807667876531E-11"
        izz="1.28084700117448E-07" />
    </inertial>
    <visual>
      <origin
        xyz="0 0 0"
        rpy="0 0 0" />
      <geometry>
        <mesh
          filename="meshes/pinky_distal.STL" />
      </geometry>
      <material
        name="">
        <color
          rgba="0.792156862745098 0.819607843137255 0.929411764705882 1" />
      </material>
    </visual>
    <collision>
      <origin
        xyz="0 0 0"
        rpy="0 0 0" />
      <geometry>
        <mesh
          filename="meshes/pinky_distal.STL" />
      </geometry>
    </collision>
  </link>
  <joint
    name="pinky_dip"
    type="revolute">
    <origin
      xyz="0.00683437962777891 0 0.0310063099184415"
      rpy="0 0 0" />
    <parent
      link="pinky_middle" />
    <child
      link="pinky_distal" />
    <axis
      xyz="0 1 0" />
    <limit
      lower="0"
      upper="1.46"
      effort="1"
      velocity="1" />
    <mimic
      joint="pinky_pip"
      multiplier="1.028"
      offset="0" />
  </joint>
  <link
    name="ring_metacarpals">
    <inertial>
      <origin
        xyz="0.00922348562569902 2.30811796148589E-05 0.0496731702739551"
        rpy="0 0 0" />
      <mass
        value="0.0106056306465452" />
      <inertia
        ixx="1.2347526272162E-06"
        ixy="-4.66286174910378E-10"
        ixz="9.99490097497798E-08"
        iyy="1.22617094720336E-06"
        iyz="-9.43339333484491E-10"
        izz="4.36646169386253E-07" />
    </inertial>
    <visual>
      <origin
        xyz="0 0 0"
        rpy="0 0 0" />
      <geometry>
        <mesh
          filename="meshes/ring_metacarpals.STL" />
      </geometry>
      <material
        name="">
        <color
          rgba="0.792156862745098 0.819607843137255 0.929411764705882 1" />
      </material>
    </visual>
    <collision>
      <origin
        xyz="0 0 0"
        rpy="0 0 0" />
      <geometry>
        <mesh
          filename="meshes/ring_metacarpals.STL" />
      </geometry>
    </collision>
  </link>
  <joint
    name="ring_mcp_roll"
    type="revolute">
    <origin
      xyz="-0.0098 0.01175 0.1481"
      rpy="0 0 0" />
    <parent
      link="wrist_base_link" />
    <child
      link="ring_metacarpals" />
    <axis
      xyz="-1 0 0" />
    <limit
      lower="-0.26"
      upper="0.26"
      effort="1"
      velocity="1" />
  </joint>
  <link
    name="ring_proximal">
    <inertial>
      <origin
        xyz="-0.00109761372342099 2.39635444646558E-05 0.0515721139223994"
        rpy="0 0 0" />
      <mass
        value="0.0102151193135347" />
      <inertia
        ixx="1.22426283620879E-06"
        ixy="-4.66286174910364E-10"
        ixz="9.99490097497798E-08"
        iyy="1.21857214763037E-06"
        iyz="-9.43339333484491E-10"
        izz="4.21116026244459E-07" />
    </inertial>
    <visual>
      <origin
        xyz="0 0 0"
        rpy="0 0 0" />
      <geometry>
        <mesh
          filename="meshes/ring_proximal.STL" />
      </geometry>
      <material
        name="">
        <color
          rgba="0.792156862745098 0.819607843137255 0.929411764705882 1" />
      </material>
    </visual>
    <collision>
      <origin
        xyz="0 0 0"
        rpy="0 0 0" />
      <geometry>
        <mesh
          filename="meshes/ring_proximal.STL" />
      </geometry>
    </collision>
  </link>
  <joint
    name="ring_mcp_pitch"
    type="revolute">
    <origin
      xyz="0.0105 0 0"
      rpy="0 0 0" />
    <parent
      link="ring_metacarpals" />
    <child
      link="ring_proximal" />
    <axis
      xyz="0 1 0" />
    <limit
      lower="0"
      upper="1.3"
      effort="1"
      velocity="1" />
  </joint>
  <link
    name="ring_middle">
    <inertial>
      <origin
        xyz="0.00153702658561409 1.43435946559078E-05 0.0294794862558192"
        rpy="0 0 0" />
      <mass
        value="0.00570037103561131" />
      <inertia
        ixx="4.91195536611223E-07"
        ixy="-4.8585462980859E-10"
        ixz="3.6908072082007E-08"
        iyy="4.46377325281286E-07"
        iyz="-1.11190354026083E-09"
        izz="2.67214212022937E-07" />
    </inertial>
    <visual>
      <origin
        xyz="0 0 0"
        rpy="0 0 0" />
      <geometry>
        <mesh
          filename="meshes/ring_middle.STL" />
      </geometry>
      <material
        name="">
        <color
          rgba="0.792156862745098 0.819607843137255 0.929411764705882 1" />
      </material>
    </visual>
    <collision>
      <origin
        xyz="0 0 0"
        rpy="0 0 0" />
      <geometry>
        <mesh
          filename="meshes/ring_middle.STL" />
      </geometry>
    </collision>
  </link>
  <joint
    name="ring_pip"
    type="revolute">
    <origin
      xyz="-0.00349999999999933 0 0.0448999999999999"
      rpy="0 0 0" />
    <parent
      link="ring_proximal" />
    <child
      link="ring_middle" />
    <axis
      xyz="0 1 0" />
    <limit
      lower="0"
      upper="1.42"
      effort="1"
      velocity="1" />
  </joint>
  <link
    name="ring_distal">
    <inertial>
      <origin
        xyz="-0.00654409780333141 -3.02641738392229E-07 0.00867928524924297"
        rpy="0 0 0" />
      <mass
        value="0.00313066786229928" />
      <inertia
        ixx="2.09660673403309E-07"
        ixy="1.41141645486377E-11"
        ixz="5.29697122303542E-08"
        iyy="2.07629486397543E-07"
        iyz="4.76803674655192E-11"
        izz="1.28084772145898E-07" />
    </inertial>
    <visual>
      <origin
        xyz="0 0 0"
        rpy="0 0 0" />
      <geometry>
        <mesh
          filename="meshes/ring_distal.STL" />
      </geometry>
      <material
        name="">
        <color
          rgba="0.792156862745098 0.819607843137255 0.929411764705882 1" />
      </material>
    </visual>
    <collision>
      <origin
        xyz="0 0 0"
        rpy="0 0 0" />
      <geometry>
        <mesh
          filename="meshes/ring_distal.STL" />
      </geometry>
    </collision>
  </link>
  <joint
    name="ring_dip"
    type="revolute">
    <origin
      xyz="0.00683437962777891 0 0.0310063099184415"
      rpy="0 0 0" />
    <parent
      link="ring_middle" />
    <child
      link="ring_distal" />
    <axis
      xyz="0 1 0" />
    <limit
      lower="0"
      upper="1.46"
      effort="1"
      velocity="1" />
    <mimic
      joint="ring_pip"
      multiplier="1.028"
      offset="0" />
  </joint>
  <link
    name="middle_metacarpals">
    <inertial>
      <origin
        xyz="0.00922348527610099 2.30813403685193E-05 0.0496731658762038"
        rpy="0 0 0" />
      <mass
        value="0.0106056292930373" />
      <inertia
        ixx="1.23475260594908E-06"
        ixy="-4.66299333018906E-10"
        ixz="9.99489919177558E-08"
        iyy="1.22617085881826E-06"
        iyz="-9.43336351634279E-10"
        izz="4.36646077200118E-07" />
    </inertial>
    <visual>
      <origin
        xyz="0 0 0"
        rpy="0 0 0" />
      <geometry>
        <mesh
          filename="meshes/middle_metacarpals.STL" />
      </geometry>
      <material
        name="">
        <color
          rgba="0.792156862745098 0.819607843137255 0.929411764705882 1" />
      </material>
    </visual>
    <collision>
      <origin
        xyz="0 0 0"
        rpy="0 0 0" />
      <geometry>
        <mesh
          filename="meshes/middle_metacarpals.STL" />
      </geometry>
    </collision>
  </link>
  <joint
    name="middle_mcp_roll"
    type="revolute">
    <origin
      xyz="-0.0098 -0.01175 0.1526"
      rpy="0 0 0" />
    <parent
      link="wrist_base_link" />
    <child
      link="middle_metacarpals" />
    <axis
      xyz="-1 0 0" />
    <limit
      lower="-0.26"
      upper="0.26"
      effort="1"
      velocity="1" />
  </joint>
  <link
    name="middle_proximal">
    <inertial>
      <origin
        xyz="-0.0010976140626793 2.39637114806679E-05 0.0515721096081383"
        rpy="0 0 0" />
      <mass
        value="0.0102151179600268" />
      <inertia
        ixx="1.22426281494167E-06"
        ixy="-4.66299333018934E-10"
        ixz="9.99489919177558E-08"
        iyy="1.21857205924526E-06"
        iyz="-9.43336351634289E-10"
        izz="4.21115934058324E-07" />
    </inertial>
    <visual>
      <origin
        xyz="0 0 0"
        rpy="0 0 0" />
      <geometry>
        <mesh
          filename="meshes/middle_proximal.STL" />
      </geometry>
      <material
        name="">
        <color
          rgba="0.792156862745098 0.819607843137255 0.929411764705882 1" />
      </material>
    </visual>
    <collision>
      <origin
        xyz="0 0 0"
        rpy="0 0 0" />
      <geometry>
        <mesh
          filename="meshes/middle_proximal.STL" />
      </geometry>
    </collision>
  </link>
  <joint
    name="middle_mcp_pithch"
    type="revolute">
    <origin
      xyz="0.0105 0 0"
      rpy="0 0 0" />
    <parent
      link="middle_metacarpals" />
    <child
      link="middle_proximal" />
    <axis
      xyz="0 1 0" />
    <limit
      lower="0"
      upper="1.3"
      effort="1"
      velocity="1" />
  </joint>
  <link
    name="middle_middle">
    <inertial>
      <origin
        xyz="0.00153702577218708 1.43438916660465E-05 0.0294794839400529"
        rpy="0 0 0" />
      <mass
        value="0.00570036968210336" />
      <inertia
        ixx="4.91195515344098E-07"
        ixy="-4.85867787917128E-10"
        ixz="3.69080542499819E-08"
        iyy="4.46377236896178E-07"
        iyz="-1.11190055841084E-09"
        izz="2.67214119836802E-07" />
    </inertial>
    <visual>
      <origin
        xyz="0 0 0"
        rpy="0 0 0" />
      <geometry>
        <mesh
          filename="meshes/middle_middle.STL" />
      </geometry>
      <material
        name="">
        <color
          rgba="0.792156862745098 0.819607843137255 0.929411764705882 1" />
      </material>
    </visual>
    <collision>
      <origin
        xyz="0 0 0"
        rpy="0 0 0" />
      <geometry>
        <mesh
          filename="meshes/middle_middle.STL" />
      </geometry>
    </collision>
  </link>
  <joint
    name="middle_pip"
    type="revolute">
    <origin
      xyz="-0.00349999999999933 0 0.0448999999999999"
      rpy="0 0 0" />
    <parent
      link="middle_proximal" />
    <child
      link="middle_middle" />
    <axis
      xyz="0 1 0" />
    <limit
      lower="0"
      upper="1.42"
      effort="1"
      velocity="1" />
  </joint>
  <link
    name="middle_distal">
    <inertial>
      <origin
        xyz="-0.00654409982344856 -3.02107269506413E-07 0.00867928544515167"
        rpy="0 0 0" />
      <mass
        value="0.00313066650879136" />
      <inertia
        ixx="2.09660652136187E-07"
        ixy="1.41010064396412E-11"
        ixz="5.29696943983292E-08"
        iyy="2.07629398012437E-07"
        iyz="4.76833493153665E-11"
        izz="1.28084679959763E-07" />
    </inertial>
    <visual>
      <origin
        xyz="0 0 0"
        rpy="0 0 0" />
      <geometry>
        <mesh
          filename="meshes/middle_distal.STL" />
      </geometry>
      <material
        name="">
        <color
          rgba="0.792156862745098 0.819607843137255 0.929411764705882 1" />
      </material>
    </visual>
    <collision>
      <origin
        xyz="0 0 0"
        rpy="0 0 0" />
      <geometry>
        <mesh
          filename="meshes/middle_distal.STL" />
      </geometry>
    </collision>
  </link>
  <joint
    name="middle_dip"
    type="revolute">
    <origin
      xyz="0.0068343796277789 0 0.0310063099184415"
      rpy="0 0 0" />
    <parent
      link="middle_middle" />
    <child
      link="middle_distal" />
    <axis
      xyz="0 1 0" />
    <limit
      lower="0"
      upper="1.46"
      effort="0"
      velocity="0" />
    <mimic
      joint="middle_pip"
      multiplier="1.028"
      offset="0" />
  </joint>
  <link
    name="index_metacarpals">
    <inertial>
      <origin
        xyz="0.00922348517515974 2.30813144259656E-05 0.0496731668110548"
        rpy="0 0 0" />
      <mass
        value="0.0106056295038298" />
      <inertia
        ixx="1.23475261048644E-06"
        ixy="-4.66299856610249E-10"
        ixz="9.99490024309792E-08"
        iyy="1.22617087783116E-06"
        iyz="-9.43335572821977E-10"
        izz="4.36646095800995E-07" />
    </inertial>
    <visual>
      <origin
        xyz="0 0 0"
        rpy="0 0 0" />
      <geometry>
        <mesh
          filename="meshes/index_metacarpals.STL" />
      </geometry>
      <material
        name="">
        <color
          rgba="0.792156862745098 0.819607843137255 0.929411764705882 1" />
      </material>
    </visual>
    <collision>
      <origin
        xyz="0 0 0"
        rpy="0 0 0" />
      <geometry>
        <mesh
          filename="meshes/index_metacarpals.STL" />
      </geometry>
    </collision>
  </link>
  <joint
    name="index_mcp_roll"
    type="revolute">
    <origin
      xyz="-0.0098 -0.03525 0.1481"
      rpy="0 0 0" />
    <parent
      link="wrist_base_link" />
    <child
      link="index_metacarpals" />
    <axis
      xyz="-1 0 0" />
    <limit
      lower="-0.26"
      upper="0.26"
      effort="1"
      velocity="1" />
  </joint>
  <link
    name="index_proximal">
    <inertial>
      <origin
        xyz="-0.00109761417117109 2.39636845281166E-05 0.0515721105395422"
        rpy="0 0 0" />
      <mass
        value="0.0102151181708194" />
      <inertia
        ixx="1.22426281947903E-06"
        ixy="-4.66299856610362E-10"
        ixz="9.99490024309789E-08"
        iyy="1.21857207825817E-06"
        iyz="-9.4333557282234E-10"
        izz="4.21115952659201E-07" />
    </inertial>
    <visual>
      <origin
        xyz="0 0 0"
        rpy="0 0 0" />
      <geometry>
        <mesh
          filename="meshes/index_proximal.STL" />
      </geometry>
      <material
        name="">
        <color
          rgba="0.792156862745098 0.819607843137255 0.929411764705882 1" />
      </material>
    </visual>
    <collision>
      <origin
        xyz="0 0 0"
        rpy="0 0 0" />
      <geometry>
        <mesh
          filename="meshes/index_proximal.STL" />
      </geometry>
    </collision>
  </link>
  <joint
    name="index_mcp_pitch"
    type="revolute">
    <origin
      xyz="0.0105 0 0"
      rpy="0 0 0" />
    <parent
      link="index_metacarpals" />
    <child
      link="index_proximal" />
    <axis
      xyz="0 1 0" />
    <limit
      lower="0"
      upper="1.3"
      effort="1"
      velocity="1" />
  </joint>
  <link
    name="index_middle">
    <inertial>
      <origin
        xyz="0.00153702560976933 1.43438437225918E-05 0.0294794847657489"
        rpy="0 0 0" />
      <mass
        value="0.00570036989289596" />
      <inertia
        ixx="4.91195519881467E-07"
        ixy="-4.85868311508675E-10"
        ixz="3.69080647632045E-08"
        iyy="4.4637725590909E-07"
        iyz="-1.11189977959848E-09"
        izz="2.67214138437681E-07" />
    </inertial>
    <visual>
      <origin
        xyz="0 0 0"
        rpy="0 0 0" />
      <geometry>
        <mesh
          filename="meshes/index_middle.STL" />
      </geometry>
      <material
        name="">
        <color
          rgba="0.792156862745098 0.819607843137255 0.929411764705882 1" />
      </material>
    </visual>
    <collision>
      <origin
        xyz="0 0 0"
        rpy="0 0 0" />
      <geometry>
        <mesh
          filename="meshes/index_middle.STL" />
      </geometry>
    </collision>
  </link>
  <joint
    name="index_pip"
    type="revolute">
    <origin
      xyz="-0.0035 0 0.0449"
      rpy="0 0 0" />
    <parent
      link="index_proximal" />
    <child
      link="index_middle" />
    <axis
      xyz="0 1 0" />
    <limit
      lower="0"
      upper="1.42"
      effort="1"
      velocity="1" />
  </joint>
  <link
    name="index_distal">
    <inertial>
      <origin
        xyz="-0.00654410005064934 -3.02193579465593E-07 0.00867928625923448"
        rpy="0 0 0" />
      <mass
        value="0.00313066671958391" />
      <inertia
        ixx="2.09660656673553E-07"
        ixy="1.41004828483991E-11"
        ixz="5.29697049115486E-08"
        iyy="2.07629417025346E-07"
        iyz="4.76841281269501E-11"
        izz="1.2808469856064E-07" />
    </inertial>
    <visual>
      <origin
        xyz="0 0 0"
        rpy="0 0 0" />
      <geometry>
        <mesh
          filename="meshes/index_distal.STL" />
      </geometry>
      <material
        name="">
        <color
          rgba="0.792156862745098 0.819607843137255 0.929411764705882 1" />
      </material>
    </visual>
    <collision>
      <origin
        xyz="0 0 0"
        rpy="0 0 0" />
      <geometry>
        <mesh
          filename="meshes/index_distal.STL" />
      </geometry>
    </collision>
  </link>
  <joint
    name="index_dip"
    type="revolute">
    <origin
      xyz="0.00683437964319216 0 0.0310063099206068"
      rpy="0 0 0" />
    <parent
      link="index_middle" />
    <child
      link="index_distal" />
    <axis
      xyz="0 1 0" />
    <limit
      lower="0"
      upper="1.46"
      effort="1"
      velocity="1" />
    <mimic
      joint="index_pip"
      multiplier="1.028"
      offset="0" />
  </joint>
  <link
    name="thumb_metacarpals_base1">
    <inertial>
      <origin
        xyz="0.0522211716804254 -0.0454599064159455 -0.00986071583612912"
        rpy="0 0 0" />
      <mass
        value="0.0451816191171156" />
      <inertia
        ixx="1.33720303293515E-05"
        ixy="1.97841544753504E-06"
        ixz="5.44018339817954E-07"
        iyy="5.64870376332633E-06"
        iyz="-5.09522920532833E-07"
        izz="1.06302220332239E-05" />
    </inertial>
    <visual>
      <origin
        xyz="0 0 0"
        rpy="0 0 0" />
      <geometry>
        <mesh
          filename="meshes/thumb_metacarpals_base1.STL" />
      </geometry>
      <material
        name="">
        <color
          rgba="0.792156862745098 0.819607843137255 0.929411764705882 1" />
      </material>
    </visual>
    <collision>
      <origin
        xyz="0 0 0"
        rpy="0 0 0" />
      <geometry>
        <mesh
          filename="meshes/thumb_metacarpals_base1.STL" />
      </geometry>
    </collision>
  </link>
  <joint
    name="thumb_cmc_yaw"
    type="revolute">
    <origin
      xyz="0 -0.01 0.0436"
      rpy="0 0 0" />
    <parent
      link="wrist_base_link" />
    <child
      link="thumb_metacarpals_base1" />
    <axis
      xyz="-1 0 0" />
    <limit
      lower="0"
      upper="1.63"
      effort="1"
      velocity="1" />
  </joint>
  <link
    name="thumb_metacarpals_base2">
    <inertial>
      <origin
        xyz="4.38270965860271E-05 0.0279058262949063 0.0562271342471901"
        rpy="0 0 0" />
      <mass
        value="0.0354001877801745" />
      <inertia
        ixx="1.07007295659827E-05"
        ixy="-1.83607311978726E-08"
        ixz="-2.92612663251038E-08"
        iyy="7.19561574529478E-06"
        iyz="-2.70699473772806E-06"
        izz="4.57857851921663E-06" />
    </inertial>
    <visual>
      <origin
        xyz="0 0 0"
        rpy="0 0 0" />
      <geometry>
        <mesh
          filename="meshes/thumb_metacarpals_base2.STL" />
      </geometry>
      <material
        name="">
        <color
          rgba="0.745098039215686 0 0 1" />
      </material>
    </visual>
    <collision>
      <origin
        xyz="0 0 0"
        rpy="0 0 0" />
      <geometry>
        <mesh
          filename="meshes/thumb_metacarpals_base2.STL" />
      </geometry>
    </collision>
  </link>
  <joint
    name="thumb_cmc_roll"
    type="revolute">
    <origin
      xyz="0.039005 0 0"
      rpy="2.2385 -0.22166 0.27191" />
    <parent
      link="thumb_metacarpals_base1" />
    <child
      link="thumb_metacarpals_base2" />
    <axis
      xyz="0 1 0" />
    <limit
      lower="0"
      upper="1.54"
      effort="1"
      velocity="1" />
  </joint>
  <link
    name="thumb_metacarpals">
    <inertial>
      <origin
        xyz="-4.35183362775191E-05 0.00471442761063823 0.0475067972416183"
        rpy="0 0 0" />
      <mass
        value="0.0345477440243795" />
      <inertia
        ixx="1.0636421657262E-05"
        ixy="-1.06627018885586E-09"
        ixz="-3.45872919537203E-08"
        iyy="8.8564538487859E-06"
        iyz="-1.92980134070468E-07"
        izz="2.84992346326571E-06" />
    </inertial>
    <visual>
      <origin
        xyz="0 0 0"
        rpy="0 0 0" />
      <geometry>
        <mesh
          filename="meshes/thumb_metacarpals.STL" />
      </geometry>
      <material
        name="">
        <color
          rgba="0.792156862745098 0.819607843137255 0.933333333333333 1" />
      </material>
    </visual>
    <collision>
      <origin
        xyz="0 0 0"
        rpy="0 0 0" />
      <geometry>
        <mesh
          filename="meshes/thumb_metacarpals.STL" />
      </geometry>
    </collision>
  </link>
  <joint
    name="thumb_cmc_pitch"
    type="revolute">
    <origin
      xyz="8.7527E-05 0.0005 0.0188"
      rpy="-0.52959 0 0" />
    <parent
      link="thumb_metacarpals_base2" />
    <child
      link="thumb_metacarpals" />
    <axis
      xyz="-1 0 0" />
    <limit
      lower="0"
      upper="0.91"
      effort="1"
      velocity="1" />
  </joint>
  <link
    name="thumb_proximal">
    <inertial>
      <origin
        xyz="-0.000141393892028122 -0.00102081214561522 0.0300815252650002"
        rpy="0 0 0" />
      <mass
        value="0.0114709346933904" />
      <inertia
        ixx="1.07625871864997E-06"
        ixy="1.21044715931267E-09"
        ixz="3.9917669253257E-09"
        iyy="8.38127104088121E-07"
        iyz="1.36525734723535E-08"
        izz="4.11578623666983E-07" />
    </inertial>
    <visual>
      <origin
        xyz="0 0 0"
        rpy="0 0 0" />
      <geometry>
        <mesh
          filename="meshes/thumb_proximal.STL" />
      </geometry>
      <material
        name="">
        <color
          rgba="0.490196078431373 0.490196078431373 0.490196078431373 1" />
      </material>
    </visual>
    <collision>
      <origin
        xyz="0 0 0"
        rpy="0 0 0" />
      <geometry>
        <mesh
          filename="meshes/thumb_proximal.STL" />
      </geometry>
    </collision>
  </link>
  <joint
    name="thumb_mcp"
    type="revolute">
    <origin
      xyz="0 0.0076743 0.055704"
      rpy="0 0 0" />
    <parent
      link="thumb_metacarpals" />
    <child
      link="thumb_proximal" />
    <axis
      xyz="-1 0 0" />
    <limit
      lower="0"
      upper="1.29"
      effort="1"
      velocity="1" />
  </joint>
  <link
    name="thumb_distal">
    <inertial>
      <origin
        xyz="-1.99616972707262E-05 0.000600374519152715 0.0111103763380498"
        rpy="0 0 0" />
      <mass
        value="0.00587670446951898" />
      <inertia
        ixx="4.41999423944627E-07"
        ixy="2.64731823033761E-10"
        ixz="-9.63082925099247E-10"
        iyy="3.61807914994116E-07"
        iyz="9.50727111679994E-08"
        izz="1.64385089076622E-07" />
    </inertial>
    <visual>
      <origin
        xyz="0 0 0"
        rpy="0 0 0" />
      <geometry>
        <mesh
          filename="meshes/thumb_distal.STL" />
      </geometry>
      <material
        name="">
        <color
          rgba="0.807843137254902 0.843137254901961 0.901960784313726 1" />
      </material>
    </visual>
    <collision>
      <origin
        xyz="0 0 0"
        rpy="0 0 0" />
      <geometry>
        <mesh
          filename="meshes/thumb_distal.STL" />
      </geometry>
    </collision>
  </link>
  <joint
    name="thumb_dip"
    type="revolute">
    <origin
      xyz="0 -0.0010918 0.034545"
      rpy="0 0 0" />
    <parent
      link="thumb_proximal" />
    <child
      link="thumb_distal" />
    <axis
      xyz="-1 0 0" />
    <limit
      lower="0"
      upper="1.29"
      effort="1"
      velocity="1" />
    <mimic
      joint="thumb_mcp"
      multiplier="1"
      offset="0" />
  </joint>
</robot>
